<?xml version="1.0"?>
<robot xmlns:xacro="http://www.ros.org/wiki/xacro" >

    <xacro:include filename="inertial_macros.xacro"/>

    <material name="white">
        <color rgba="1 1 1 1" />
    </material>

    <material name="orange">
        <color rgba="1 0.3 0.1 1"/>
    </material>

    <material name="blue">
        <color rgba="0.2 0.2 1 1"/>
    </material>

    <material name="black">
        <color rgba="0 0 0 1"/>
    </material>
    <material name="red">
        <color rgba="1 0 0 1"/>
    </material>

    <!-- BASE LINK -->

    <link name="base_link">

    </link>


    <!-- CHASSIS LINK -->

    <joint name="chassis_joint" type="fixed">
        <parent link="base_link"/>
        <child link="chassis"/>
        <origin xyz="-0.1 0 0"/>
    </joint>

    <link name="chassis">
        <visual>
            <origin xyz="0.55 0 0.20375"/>
            <geometry>
                <box size="1.10 0.52 0.1975"/>
            </geometry>
            <material name="white"/>
        </visual>
        <visual>
            <origin xyz="0.0475 0 0.07875"/>
            <geometry>
                <box size="0.095 0.52 0.0525"/>
            </geometry>
            <material name="white"/>
        </visual>
        <visual>
            <origin xyz="0.475 0 0.07875"/>
            <geometry>
                <box size="0.35 0.52 0.0525"/>
            </geometry>
            <material name="white"/>
        </visual>
        <visual>
            <origin xyz="1.0025 0 0.07875"/>
            <geometry>
                <box size="0.195 0.52 0.0525"/>
            </geometry>
            <material name="white"/>
        </visual>
        
        <collision>
            <origin xyz="0.55 0 0.20375"/>
            <geometry>
                <box size="1.10 0.52 0.1975"/>
            </geometry>
        </collision>
        <collision>
            <origin xyz="0.0475 0 0.07875"/>
            <geometry>
                <box size="0.095 0.52 0.0525"/>
            </geometry>
        </collision>
        <collision>
            <origin xyz="0.475 0 0.07875"/>
            <geometry>
                <box size="0.35 0.52 0.0525"/>
            </geometry>
        </collision>
        <collision>
            <origin xyz="1.0025 0 0.07875"/>
            <geometry>
                <box size="0.195 0.52 0.0525"/>
            </geometry>
        </collision>       
        <xacro:inertial_box mass="5.0" x="1.10" y="0.52" z="0.25">
            <origin xyz="0.55 0 0.125" rpy="0 0 0"/>
        </xacro:inertial_box>
    </link>
    <gazebo reference="chassis">
        <material>Gazebo/White</material>
    </gazebo>
    
    <!-- REAR LEFT WHEEL LINK -->

    <joint name="rear_left_wheel_joint" type="continuous">
        <parent link="chassis"/>
        <child link="rear_left_wheel"/>
        <origin xyz="0.20 0.22 0" rpy="-${pi/2} 0 0" />
        <axis xyz="0 0 1"/>
    </joint>

    <link name="rear_left_wheel">
        <visual>
            <geometry>
                <cylinder radius="0.105" length="0.08"/>
            </geometry>
            <material name="blue"/>
        </visual>
        <collision>
            <geometry>
                <cylinder radius="0.105" length="0.08"/>
            </geometry>
        </collision>
        <xacro:inertial_cylinder mass="1.0" length="0.08" radius="0.105">
            <origin xyz="0 0 0" rpy="0 0 0"/>
        </xacro:inertial_cylinder>
    </link>
    <gazebo reference="rear_left_wheel">
        <material>Gazebo/Black</material>
    </gazebo>
    <!-- REAR RIGHT WHEEL LINK -->

    <joint name="rear_right_wheel_joint" type="continuous">
        <parent link="chassis"/>
        <child link="rear_right_wheel"/>
        <origin xyz="0.20 -0.22 0"  rpy="${pi/2} 0 0" />
        <axis xyz="0 0 -1"/>
    </joint>

    <link name="rear_right_wheel">
        <visual>
            <geometry>
                <cylinder radius="0.105" length="0.08"/>
            </geometry>
            <material name="blue"/>
        </visual>
        <collision>
            <geometry>
                <cylinder radius="0.105" length="0.08"/>
            </geometry>
        </collision>
        <xacro:inertial_cylinder mass="1.0" length="0.08" radius="0.105">
            <origin xyz="0 0 0" rpy="0 0 0"/>
        </xacro:inertial_cylinder>
    </link>
    <gazebo reference="rear_right_wheel">
        <material>Gazebo/Black</material>
    </gazebo>
    <!-- FRONT LEFT STEERING JOINT -->
    <joint name="front_left_steering_joint" type="revolute">
        <parent link="chassis"/>
        <child link="front_left_steering"/>
        <origin xyz="0.78 0.22 0"/>
        <axis xyz="0 0 1"/>
        <limit lower="-0.31416" upper="0.31416" effort="1" velocity="1"/>

    </joint>
    <link name="front_left_steering">
    <visual>
        <origin xyz="0 0 0"/>
        <geometry>
        <box size="0.001 0.001 0.001"/>
        </geometry>
        <material name="black"/>
    </visual>
    <collision>
        <origin xyz="0 0 0"/>
        <geometry>
        <box size="0.001 0.001 0.001"/>
        </geometry>
    </collision>
    <inertial>
        <mass value="0.001"/>
        <inertia ixx="1e-7" ixy="0.0" ixz="0.0" iyy="1e-7" iyz="0.0" izz="1e-7"/>
    </inertial>
    </link>

    <!-- FRONT LEFT WHEEL ROLLING JOINT -->
    <joint name="front_left_wheel_joint" type="continuous">
        <parent link="front_left_steering"/>
        <child link="front_left_wheel"/>
        <origin xyz="0 0 0" rpy="-${pi/2} 0 0"/>
        <axis xyz="0 0 1"/>
    </joint>
    <link name="front_left_wheel">
        <visual>
            <geometry>
                <cylinder radius="0.105" length="0.08"/>
            </geometry>
            <material name="orange"/>
        </visual>
        <collision>
            <geometry>
                <cylinder radius="0.105" length="0.08"/>
            </geometry>
        </collision>
        <xacro:inertial_cylinder mass="1.0" length="0.08" radius="0.105">
            <origin xyz="0 0 0" rpy="0 0 0"/>
        </xacro:inertial_cylinder>
    </link>
    <gazebo reference="front_left_wheel">
        <material>Gazebo/Black</material>
        <mul1 value="0.001"/>
        <mul2 value="0.001"/>
    </gazebo>
    <!-- FRONT RIGHT STEERING JOINT -->
    <joint name="front_right_steering_joint" type="revolute">
        <parent link="chassis"/>
        <child link="front_right_steering"/>
        <origin xyz="0.78 -0.22 0"/>
        <axis xyz="0 0 1"/>
        <limit lower="-0.31416" upper="0.31416" effort="1" velocity="1"/>

    </joint>
    <link name="front_right_steering">
    <visual>
        <origin xyz="0 0 0"/>
        <geometry>
        <box size="0.001 0.001 0.001"/>
        </geometry>
        <material name="black"/>
    </visual>
    <collision>
        <origin xyz="0 0 0"/>
        <geometry>
        <box size="0.001 0.001 0.001"/>
        </geometry>
    </collision>
    <inertial>
        <mass value="0.001"/>
        <inertia ixx="1e-7" ixy="0.0" ixz="0.0" iyy="1e-7" iyz="0.0" izz="1e-7"/>
    </inertial>
    </link>

    <!-- FRONT RIGHTWHEEL ROLLING JOINT -->
    <joint name="front_right_wheel_joint" type="continuous">
        <parent link="front_right_steering"/>
        <child link="front_right_wheel"/>
        <origin xyz="0 0 0" rpy="${pi/2} 0 0"/>
        <axis xyz="0 0 1"/>
    </joint>
    <link name="front_right_wheel">
        <visual>
            <geometry>
                <cylinder radius="0.105" length="0.08"/>
            </geometry>
            <material name="blue"/>
        </visual>
        <collision>
            <geometry>
                <cylinder radius="0.105" length="0.08"/>
            </geometry>
        </collision>
        <xacro:inertial_cylinder mass="1.0" length="0.08" radius="0.105">
            <origin xyz="0 0 0" rpy="0 0 0"/>
        </xacro:inertial_cylinder>
    </link>
    <gazebo reference="front_right_wheel">
        <material>Gazebo/Black</material>
        <mul1 value="0.001"/>
        <mul2 value="0.001"/>
    </gazebo>
</robot>